<?xml version="1.0"?>
<!-- =================================================================================== -->
<!-- |    
This document was autogenerated by xacro from 
/home/pavan/Downloads/SUTD/DesignProject/navrl-bench/m3_ros2_ws/install/m3_ros2/share/m3_ros2/urdf/ROSMASTER-M3.xacro | -->
<!-- |    EDITING THIS FILE BY HAND IS NOT RECOMMENDED                                 | -->
<!-- =================================================================================== -->
<robot name="ROSMASTER-M3">
  <!-- depth camera type -->
  <material name="black">
    <color rgba="0.1 0.1 0.1 1.0"/>
  </material>
  <material name="blue">
    <color rgba="0.0 0.0 0.8 1.0"/>
  </material>
  <material name="green">
    <color rgba="0.4 0.9 0.4 1.0"/>
  </material>
  <material name="gray">
    <color rgba="0.7 0.7 0.7 1.0"/>
  </material>
  <material name="darkgray">
    <color rgba="0.3 0.3 0.3 1.0"/>
  </material>
  <material name="red">
    <color rgba="0.8 0.0 0.0 1.0"/>
  </material>
  <material name="white">
    <color rgba="1.0 1.0 1.0 1.0"/>
  </material>
  <material name="yellow">
    <color rgba="0.8 0.8 0.0 1.0"/>
  </material>
  <!-- lidar template -->
  <!--base_footprint投影点-->
  <link name="base_footprint"> 
</link>
  <joint name="base-Joint" type="fixed">
    <origin rpy="0 0 0" xyz="0 0 0.03"/>
    <parent link="base_footprint"/>
    <child link="base_link"/>
  </joint>
  <!--base_link底盘-->
  <link name="base_link">
    <inertial>
      <origin rpy="0 0 0" xyz="-0.02984496350171 -0.000481153572635691 0.0765287728161752"/>
      <mass value="0.99934444005899"/>
      <inertia ixx="0.00160080186836152" ixy="3.98571758764143E-06" ixz="-0.000131328647411587" iyy="0.00221164246632588" iyz="5.5986256573897E-07" izz="0.00344837201415694"/>
    </inertial>
    <visual>
      <origin rpy="0 0 0" xyz="0 0 0"/>
      <geometry>
        <mesh filename="../meshes/base_link.STL"/>
      </geometry>
      <material name="">
        <color rgba="0.776470588235294 0.756862745098039 0.737254901960784 1"/>
      </material>
    </visual>
    <collision>
      <origin rpy="0 0 0" xyz="0 0 0"/>
      <geometry>
        <mesh filename="../meshes/base_link.STL"/>
      </geometry>
    </collision>
  </link>
  <!--depth camera -->
  <link name="camera_link">
    <inertial>
      <origin rpy="0 0 0" xyz="-0.000338233024565315 0.000873950945523536 0.000135673799547986"/>
      <mass value="0.0238818467584584"/>
      <inertia ixx="1.37649367410834E-05" ixy="1.24830471237178E-07" ixz="1.37445274067818E-08" iyy="1.59984966748044E-06" iyz="2.27879404919167E-08" izz="1.39784153878035E-05"/>
    </inertial>
    <visual>
      <origin rpy="0 0 0" xyz="0 0 0"/>
      <geometry>
        <mesh filename="../meshes/camera_Link.STL"/>
      </geometry>
      <material name="">
        <color rgba="1 1 1 1"/>
      </material>
    </visual>
    <collision>
      <origin rpy="0 1.57 0" xyz="0 0 0"/>
      <geometry>
        <mesh filename="../meshes/camera_Link.STL"/>
      </geometry>
    </collision>
  </link>
  <joint name="camera-Joint" type="fixed">
    <origin rpy="0 0 0" xyz="0.089279 0 0.087335"/>
    <parent link="base_link"/>
    <child link="camera_link"/>
  </joint>
  <!-- ansijan camera -->
  <link name="ascamera_hp60c_camera_link_0"> </link>
  <joint name="simcamera-Joint" type="continuous">
    <origin rpy="-1.57 0 -1.57" xyz="0 0 0"/>
    <parent link="camera_link"/>
    <child link="ascamera_hp60c_camera_link_0"/>
    <axis xyz="0 0 1"/>
  </joint>
  <!-- <xacro:if value="${camera_type == 'dabai_dcw2'}">
<link name="${prefix}${ascamera_hp60c_camera_link_0}"> </link> <joint name="${prefix}simcamera-Joint" type="fixed"> <origin xyz="0 0 0" rpy="0 0 0" /> <parent link="${prefix}camera_link" /> <child link="${prefix}${ascamera_hp60c_camera_link_0}" /> </joint>
</xacro:if> -->
  <!--IMU传感器  -->
  <link name="imu_frame">
    <inertial>
      <origin rpy="0 0 0" xyz="-0.00179025847750633 0.00264720509651104 9.90269646727743E-05"/>
      <mass value="0.0189075829050396"/>
      <inertia ixx="4.73477803493336E-06" ixy="1.6745074479594E-09" ixz="8.93836267742825E-10" iyy="2.12052097184731E-06" iyz="-3.87767258085538E-10" izz="6.74576051815791E-06"/>
    </inertial>
    <visual>
      <origin rpy="0 0 0" xyz="0 0 0"/>
      <geometry>
        <mesh filename="../meshes/IMU_Link.STL"/>
      </geometry>
      <material name="">
        <color rgba="1 1 1 1"/>
      </material>
    </visual>
    <collision>
      <origin rpy="0 0 0" xyz="0 0 0"/>
      <geometry>
        <mesh filename="../meshes/IMU_Link.STL"/>
      </geometry>
    </collision>
  </link>
  <joint name="IMU_Joint" type="fixed">
    <origin rpy="0 0  -1.5708" xyz="0.067303 0.0071499 0.053691"/>
    <parent link="base_link"/>
    <child link="imu_frame"/>
  </joint>
  <!--left front wheel  -->
  <link name="lwheel1_Link">
    <inertial>
      <origin rpy="0 0 0" xyz="1.53560272599211E-05 1.98250838429059E-06 -0.0108846203867566"/>
      <mass value="0.0989881984813495"/>
      <inertia ixx="4.45414870929911E-05" ixy="1.57090619994683E-10" ixz="2.38113616704235E-09" iyy="4.45412348155267E-05" iyz="8.43582144052669E-10" izz="7.4602274246963E-05"/>
    </inertial>
    <visual>
      <origin rpy="0 0 0" xyz="0 0 0"/>
      <geometry>
        <mesh filename="../meshes/lwheel1_Link.STL"/>
      </geometry>
      <material name="">
        <color rgba="0.298039215686275 0.298039215686275 0.298039215686275 1"/>
      </material>
    </visual>
    <collision>
      <origin rpy="0 0 0" xyz="0 0 0"/>
      <geometry>
        <mesh filename="../meshes/lwheel1_Link.STL"/>
      </geometry>
    </collision>
  </link>
  <joint name="lwheel1_Joint" type="continuous">
    <origin rpy="-1.5708 -1.5708 0" xyz="0.0795 0.09775 0.0145"/>
    <parent link="base_link"/>
    <child link="lwheel1_Link"/>
    <axis xyz="0 0 1"/>
  </joint>
  <!-- left rear wheel -->
  <link name="lwheel2_Link">
    <inertial>
      <origin rpy="0 0 0" xyz="1.28765327241931E-05 -2.45112629573135E-06 -0.0108847338593798"/>
      <mass value="0.0989867715411591"/>
      <inertia ixx="4.45411429026561E-05" ixy="3.49581085220021E-10" ixz="4.25224100985959E-10" iyy="4.45402969289142E-05" iyz="-2.52453535532053E-09" izz="7.46016514000059E-05"/>
    </inertial>
    <visual>
      <origin rpy="0 0 0" xyz="0 0 0"/>
      <geometry>
        <mesh filename="../meshes/lwheel2_Link.STL"/>
      </geometry>
      <material name="">
        <color rgba="0.298039215686275 0.298039215686275 0.298039215686275 1"/>
      </material>
    </visual>
    <collision>
      <origin rpy="0 0 0" xyz="0 0 0"/>
      <geometry>
        <mesh filename="../meshes/lwheel2_Link.STL"/>
      </geometry>
    </collision>
  </link>
  <joint name="lwheel2_Joint" type="continuous">
    <origin rpy="-1.5708 -1.5708 0" xyz="-0.0795 0.09775 0.014498"/>
    <parent link="base_link"/>
    <child link="lwheel2_Link"/>
    <axis xyz="0 0 1"/>
  </joint>
  <!--right front wheel -->
  <link name="rwheel1_Link">
    <inertial>
      <origin rpy="0 0 0" xyz="-1.44743128333881E-05 -2.39019759440406E-06 -0.0108847338867027"/>
      <mass value="0.0989867702680243"/>
      <inertia ixx="4.45411446128523E-05" ixy="3.47174208470481E-10" ixz="4.17555484487362E-10" iyy="4.45402942652055E-05" iyz="-2.52548693570598E-09" izz="7.46016508017433E-05"/>
    </inertial>
    <visual>
      <origin rpy="0 0 0" xyz="0 0 0"/>
      <geometry>
        <mesh filename="../meshes/rwheel1_Link.STL"/>
      </geometry>
      <material name="">
        <color rgba="0.298039215686275 0.298039215686275 0.298039215686275 1"/>
      </material>
    </visual>
    <collision>
      <origin rpy="0 0 0" xyz="0 0 0"/>
      <geometry>
        <mesh filename="../meshes/rwheel1_Link.STL"/>
      </geometry>
    </collision>
  </link>
  <joint name="rwheel1_Joint" type="continuous">
    <origin rpy="1.5708 1.5708 0" xyz="0.0795 -0.09775 0.0145"/>
    <parent link="base_link"/>
    <child link="rwheel1_Link"/>
    <axis xyz="0 0 1"/>
  </joint>
  <!-- right rear wheel -->
  <link name="rwheel2_Link">
    <inertial>
      <origin rpy="0 0 0" xyz="-1.53534838632473E-05 -2.00205735528119E-06 -0.0108846205927622"/>
      <mass value="0.098988198599032"/>
      <inertia ixx="4.45414873742238E-05" ixy="1.57073466808373E-10" ixz="-2.37970709300959E-09" iyy="4.45412346444611E-05" iyz="-8.4683900934824E-10" izz="7.46022743347392E-05"/>
    </inertial>
    <visual>
      <origin rpy="0 0 0" xyz="0 0 0"/>
      <geometry>
        <mesh filename="../meshes/rwheel2_Link.STL"/>
      </geometry>
      <material name="">
        <color rgba="0.298039215686275 0.298039215686275 0.298039215686275 1"/>
      </material>
    </visual>
    <collision>
      <origin rpy="0 0 0" xyz="0 0 0"/>
      <geometry>
        <mesh filename="../meshes/rwheel2_Link.STL"/>
      </geometry>
    </collision>
  </link>
  <joint name="rwheel2_Joint" type="continuous">
    <origin rpy="1.5708 1.5708 0" xyz="-0.0795 -0.09775 0.014498"/>
    <parent link="base_link"/>
    <child link="rwheel2_Link"/>
    <axis xyz="0 0 1"/>
  </joint>
  <!-- Dual lidar -->
  <!-- Right front lidar -->
  <link name="laser0_frame">
    <inertial>
      <origin rpy="0 0 0" xyz="-0.0269843281171733 0.00816587315971244 -0.0236277413611298"/>
      <mass value="0.0308225741620077"/>
      <inertia ixx="3.82222338459333E-06" ixy="1.9498522956423E-06" ixz="-3.94061068649985E-08" iyy="1.37519890249445E-05" iyz="1.02396804900856E-07" izz="1.67927144171134E-05"/>
    </inertial>
    <visual>
      <origin rpy="0 0 0" xyz="0 0 0"/>
      <geometry>
        <mesh filename="../meshes/Tmini-Plus2_1_Link.STL"/>
      </geometry>
      <material name="">
        <color rgba="0.113725490196078 0.113725490196078 0.113725490196078 1"/>
      </material>
    </visual>
    <collision>
      <origin rpy="0 0 0" xyz="0 0 0"/>
      <geometry>
        <mesh filename="../meshes/Tmini-Plus2_1_Link.STL"/>
      </geometry>
    </collision>
  </link>
  <joint name="laser_link_front_Joint" type="fixed">
    <origin rpy="0 0 0" xyz="0.10503 -0.08602 0.099466"/>
    <parent link="base_link"/>
    <child link="laser0_frame"/>
    <axis xyz="0 0 0"/>
  </joint>
  <!--left rear lidar-->
  <link name="laser1_frame">
    <inertial>
      <origin rpy="0 0 0" xyz="0.0269847162349362 -0.00816244761834535 -0.023628830709695"/>
      <mass value="0.0308225741575237"/>
      <inertia ixx="3.82201771047017E-06" ixy="1.94932291718845E-06" ixz="3.9683496469893E-08" iyy="1.37522209920578E-05" iyz="-1.02785775330184E-07" izz="1.67926881225509E-05"/>
    </inertial>
    <visual>
      <origin rpy="0 0 0" xyz="0 0 0"/>
      <geometry>
        <mesh filename="../meshes/Tmini-Plus2_2_Link.STL"/>
      </geometry>
      <material name="">
        <color rgba="0.113725490196078 0.113725490196078 0.113725490196078 1"/>
      </material>
    </visual>
    <collision>
      <origin rpy="0 0 0" xyz="0 0 0"/>
      <geometry>
        <mesh filename="../meshes/Tmini-Plus2_2_Link.STL"/>
      </geometry>
    </collision>
  </link>
  <joint name="laser_link_rear_Joint" type="fixed">
    <origin rpy="0 0 0" xyz="-0.13 0.086 0.099477"/>
    <parent link="base_link"/>
    <child link="laser1_frame"/>
    <axis xyz="0 0 0"/>
  </joint>
  <!--virtual lidar  -->
  <link name="lasersim_frame"> </link>
  <joint name="lasersim_link_Joint" type="fixed">
    <origin rpy="0 0 0" xyz="0 0 0.099466"/>
    <parent link="base_link"/>
    <child link="lasersim_frame"/>
  </joint>
  <!-- instantiate lidar -->
</robot>
